Traceback (most recent call last):
  File "<frozen runpy>", line 198, in _run_module_as_main
  File "<frozen runpy>", line 88, in _run_code
  File "/Users/abdulrahman/Documents/GitHub/shoobydo/apps/backend/.venv/lib/python3.13/site-packages/uvicorn/__main__.py", line 4, in <module>
    uvicorn.main()
    ~~~~~~~~~~~~^^
  File "/Users/abdulrahman/Documents/GitHub/shoobydo/apps/backend/.venv/lib/python3.13/site-packages/click/core.py", line 1442, in __call__
    return self.main(*args, **kwargs)
           ~~~~~~~~~^^^^^^^^^^^^^^^^^
  File "/Users/abdulrahman/Documents/GitHub/shoobydo/apps/backend/.venv/lib/python3.13/site-packages/click/core.py", line 1363, in main
    rv = self.invoke(ctx)
  File "/Users/abdulrahman/Documents/GitHub/shoobydo/apps/backend/.venv/lib/python3.13/site-packages/click/core.py", line 1226, in invoke
    return ctx.invoke(self.callback, **ctx.params)
           ~~~~~~~~~~^^^^^^^^^^^^^^^^^^^^^^^^^^^^^
  File "/Users/abdulrahman/Documents/GitHub/shoobydo/apps/backend/.venv/lib/python3.13/site-packages/click/core.py", line 794, in invoke
    return callback(*args, **kwargs)
  File "/Users/abdulrahman/Documents/GitHub/shoobydo/apps/backend/.venv/lib/python3.13/site-packages/uvicorn/main.py", line 413, in main
    run(
    ~~~^
        app,
        ^^^^
    ...<45 lines>...
        h11_max_incomplete_event_size=h11_max_incomplete_event_size,
        ^^^^^^^^^^^^^^^^^^^^^^^^^^^^^^^^^^^^^^^^^^^^^^^^^^^^^^^^^^^^
    )
    ^
  File "/Users/abdulrahman/Documents/GitHub/shoobydo/apps/backend/.venv/lib/python3.13/site-packages/uvicorn/main.py", line 580, in run
    server.run()
    ~~~~~~~~~~^^
  File "/Users/abdulrahman/Documents/GitHub/shoobydo/apps/backend/.venv/lib/python3.13/site-packages/uvicorn/server.py", line 67, in run
    return asyncio.run(self.serve(sockets=sockets))
           ~~~~~~~~~~~^^^^^^^^^^^^^^^^^^^^^^^^^^^^^
  File "/usr/local/Cellar/python@3.13/3.13.3/Frameworks/Python.framework/Versions/3.13/lib/python3.13/asyncio/runners.py", line 195, in run
    return runner.run(main)
           ~~~~~~~~~~^^^^^^
  File "/usr/local/Cellar/python@3.13/3.13.3/Frameworks/Python.framework/Versions/3.13/lib/python3.13/asyncio/runners.py", line 118, in run
    return self._loop.run_until_complete(task)
           ~~~~~~~~~~~~~~~~~~~~~~~~~~~~~^^^^^^
  File "uvloop/loop.pyx", line 1518, in uvloop.loop.Loop.run_until_complete
  File "/Users/abdulrahman/Documents/GitHub/shoobydo/apps/backend/.venv/lib/python3.13/site-packages/uvicorn/server.py", line 71, in serve
    await self._serve(sockets)
  File "/Users/abdulrahman/Documents/GitHub/shoobydo/apps/backend/.venv/lib/python3.13/site-packages/uvicorn/server.py", line 78, in _serve
    config.load()
    ~~~~~~~~~~~^^
  File "/Users/abdulrahman/Documents/GitHub/shoobydo/apps/backend/.venv/lib/python3.13/site-packages/uvicorn/config.py", line 436, in load
    self.loaded_app = import_from_string(self.app)
                      ~~~~~~~~~~~~~~~~~~^^^^^^^^^^
  File "/Users/abdulrahman/Documents/GitHub/shoobydo/apps/backend/.venv/lib/python3.13/site-packages/uvicorn/importer.py", line 19, in import_from_string
    module = importlib.import_module(module_str)
  File "/usr/local/Cellar/python@3.13/3.13.3/Frameworks/Python.framework/Versions/3.13/lib/python3.13/importlib/__init__.py", line 88, in import_module
    return _bootstrap._gcd_import(name[level:], package, level)
           ~~~~~~~~~~~~~~~~~~~~~~^^^^^^^^^^^^^^^^^^^^^^^^^^^^^^
  File "<frozen importlib._bootstrap>", line 1387, in _gcd_import
  File "<frozen importlib._bootstrap>", line 1360, in _find_and_load
  File "<frozen importlib._bootstrap>", line 1331, in _find_and_load_unlocked
  File "<frozen importlib._bootstrap>", line 935, in _load_unlocked
  File "<frozen importlib._bootstrap_external>", line 1026, in exec_module
  File "<frozen importlib._bootstrap>", line 488, in _call_with_frames_removed
  File "/Users/abdulrahman/Documents/GitHub/shoobydo/apps/backend/app/main.py", line 1, in <module>
    from fastapi import FastAPI, APIRouter
  File "/Users/abdulrahman/Documents/GitHub/shoobydo/apps/backend/.venv/lib/python3.13/site-packages/fastapi/__init__.py", line 7, in <module>
    from .applications import FastAPI as FastAPI
  File "/Users/abdulrahman/Documents/GitHub/shoobydo/apps/backend/.venv/lib/python3.13/site-packages/fastapi/applications.py", line 16, in <module>
    from fastapi import routing
  File "/Users/abdulrahman/Documents/GitHub/shoobydo/apps/backend/.venv/lib/python3.13/site-packages/fastapi/routing.py", line 25, in <module>
    from fastapi import params
  File "/Users/abdulrahman/Documents/GitHub/shoobydo/apps/backend/.venv/lib/python3.13/site-packages/fastapi/params.py", line 5, in <module>
    from fastapi.openapi.models import Example
  File "/Users/abdulrahman/Documents/GitHub/shoobydo/apps/backend/.venv/lib/python3.13/site-packages/fastapi/openapi/models.py", line 4, in <module>
    from fastapi._compat import (
    ...<6 lines>...
    )
  File "/Users/abdulrahman/Documents/GitHub/shoobydo/apps/backend/.venv/lib/python3.13/site-packages/fastapi/_compat.py", line 22, in <module>
    from fastapi.exceptions import RequestErrorModel
  File "/Users/abdulrahman/Documents/GitHub/shoobydo/apps/backend/.venv/lib/python3.13/site-packages/fastapi/exceptions.py", line 3, in <module>
    from pydantic import BaseModel, create_model
  File "/Users/abdulrahman/Documents/GitHub/shoobydo/apps/backend/.venv/lib/python3.13/site-packages/pydantic/__init__.py", line 5, in <module>
    from ._migration import getattr_migration
  File "/Users/abdulrahman/Documents/GitHub/shoobydo/apps/backend/.venv/lib/python3.13/site-packages/pydantic/_migration.py", line 4, in <module>
    from .version import version_short
  File "/Users/abdulrahman/Documents/GitHub/shoobydo/apps/backend/.venv/lib/python3.13/site-packages/pydantic/version.py", line 5, in <module>
    from pydantic_core import __version__ as __pydantic_core_version__
  File "/Users/abdulrahman/Documents/GitHub/shoobydo/apps/backend/.venv/lib/python3.13/site-packages/pydantic_core/__init__.py", line 30, in <module>
    from .core_schema import CoreConfig, CoreSchema, CoreSchemaType, ErrorType
  File "/Users/abdulrahman/Documents/GitHub/shoobydo/apps/backend/.venv/lib/python3.13/site-packages/pydantic_core/core_schema.py", line 7
    from __future__ import annotations as _annotations
    ^^^^^^^^^^^^^^^^^^^^^^^^^^^^^^^^^^^^^^^^^^^^^^^^^^
SyntaxError: from __future__ imports must occur at the beginning of the file
