/Users/abdulrahman/Documents/GitHub/shoobydo/apps/backend/.venv/lib/python3.13/site-packages/pydantic/_internal/_config.py:373: UserWarning: Valid config keys have changed in V2:
* 'orm_mode' has been renamed to 'from_attributes'
  warnings.warn(message, UserWarning)
INFO:     Started server process [17725]
INFO:     Waiting for application startup.
INFO:     Application startup complete.
INFO:     Uvicorn running on http://0.0.0.0:8805 (Press CTRL+C to quit)
ERROR:    Exception in ASGI application
Traceback (most recent call last):
  File "/Users/abdulrahman/Documents/GitHub/shoobydo/apps/backend/.venv/lib/python3.13/site-packages/sqlalchemy/engine/base.py", line 1967, in _exec_single_context
    self.dialect.do_execute(
    ~~~~~~~~~~~~~~~~~~~~~~~^
        cursor, str_statement, effective_parameters, context
        ^^^^^^^^^^^^^^^^^^^^^^^^^^^^^^^^^^^^^^^^^^^^^^^^^^^^
    )
    ^
  File "/Users/abdulrahman/Documents/GitHub/shoobydo/apps/backend/.venv/lib/python3.13/site-packages/sqlalchemy/engine/default.py", line 951, in do_execute
    cursor.execute(statement, parameters)
    ~~~~~~~~~~~~~~^^^^^^^^^^^^^^^^^^^^^^^
psycopg2.errors.UndefinedTable: relation "users" does not exist
LINE 2: FROM users 
             ^


The above exception was the direct cause of the following exception:

Traceback (most recent call last):
  File "/Users/abdulrahman/Documents/GitHub/shoobydo/apps/backend/.venv/lib/python3.13/site-packages/uvicorn/protocols/http/httptools_impl.py", line 409, in run_asgi
    result = await app(  # type: ignore[func-returns-value]
             ^^^^^^^^^^^^^^^^^^^^^^^^^^^^^^^^^^^^^^^^^^^^^^
        self.scope, self.receive, self.send
        ^^^^^^^^^^^^^^^^^^^^^^^^^^^^^^^^^^^
    )
    ^
  File "/Users/abdulrahman/Documents/GitHub/shoobydo/apps/backend/.venv/lib/python3.13/site-packages/uvicorn/middleware/proxy_headers.py", line 60, in __call__
    return await self.app(scope, receive, send)
           ^^^^^^^^^^^^^^^^^^^^^^^^^^^^^^^^^^^^
  File "/Users/abdulrahman/Documents/GitHub/shoobydo/apps/backend/.venv/lib/python3.13/site-packages/fastapi/applications.py", line 1054, in __call__
    await super().__call__(scope, receive, send)
  File "/Users/abdulrahman/Documents/GitHub/shoobydo/apps/backend/.venv/lib/python3.13/site-packages/starlette/applications.py", line 113, in __call__
    await self.middleware_stack(scope, receive, send)
  File "/Users/abdulrahman/Documents/GitHub/shoobydo/apps/backend/.venv/lib/python3.13/site-packages/starlette/middleware/errors.py", line 186, in __call__
    raise exc
  File "/Users/abdulrahman/Documents/GitHub/shoobydo/apps/backend/.venv/lib/python3.13/site-packages/starlette/middleware/errors.py", line 164, in __call__
    await self.app(scope, receive, _send)
  File "/Users/abdulrahman/Documents/GitHub/shoobydo/apps/backend/.venv/lib/python3.13/site-packages/starlette/middleware/exceptions.py", line 63, in __call__
    await wrap_app_handling_exceptions(self.app, conn)(scope, receive, send)
  File "/Users/abdulrahman/Documents/GitHub/shoobydo/apps/backend/.venv/lib/python3.13/site-packages/starlette/_exception_handler.py", line 53, in wrapped_app
    raise exc
  File "/Users/abdulrahman/Documents/GitHub/shoobydo/apps/backend/.venv/lib/python3.13/site-packages/starlette/_exception_handler.py", line 42, in wrapped_app
    await app(scope, receive, sender)
  File "/Users/abdulrahman/Documents/GitHub/shoobydo/apps/backend/.venv/lib/python3.13/site-packages/starlette/routing.py", line 716, in __call__
    await self.middleware_stack(scope, receive, send)
  File "/Users/abdulrahman/Documents/GitHub/shoobydo/apps/backend/.venv/lib/python3.13/site-packages/starlette/routing.py", line 736, in app
    await route.handle(scope, receive, send)
  File "/Users/abdulrahman/Documents/GitHub/shoobydo/apps/backend/.venv/lib/python3.13/site-packages/starlette/routing.py", line 290, in handle
    await self.app(scope, receive, send)
  File "/Users/abdulrahman/Documents/GitHub/shoobydo/apps/backend/.venv/lib/python3.13/site-packages/starlette/routing.py", line 78, in app
    await wrap_app_handling_exceptions(app, request)(scope, receive, send)
  File "/Users/abdulrahman/Documents/GitHub/shoobydo/apps/backend/.venv/lib/python3.13/site-packages/starlette/_exception_handler.py", line 53, in wrapped_app
    raise exc
  File "/Users/abdulrahman/Documents/GitHub/shoobydo/apps/backend/.venv/lib/python3.13/site-packages/starlette/_exception_handler.py", line 42, in wrapped_app
    await app(scope, receive, sender)
  File "/Users/abdulrahman/Documents/GitHub/shoobydo/apps/backend/.venv/lib/python3.13/site-packages/starlette/routing.py", line 75, in app
    response = await f(request)
               ^^^^^^^^^^^^^^^^
  File "/Users/abdulrahman/Documents/GitHub/shoobydo/apps/backend/.venv/lib/python3.13/site-packages/fastapi/routing.py", line 302, in app
    raw_response = await run_endpoint_function(
                   ^^^^^^^^^^^^^^^^^^^^^^^^^^^^
    ...<3 lines>...
    )
    ^
  File "/Users/abdulrahman/Documents/GitHub/shoobydo/apps/backend/.venv/lib/python3.13/site-packages/fastapi/routing.py", line 215, in run_endpoint_function
    return await run_in_threadpool(dependant.call, **values)
           ^^^^^^^^^^^^^^^^^^^^^^^^^^^^^^^^^^^^^^^^^^^^^^^^^
  File "/Users/abdulrahman/Documents/GitHub/shoobydo/apps/backend/.venv/lib/python3.13/site-packages/starlette/concurrency.py", line 38, in run_in_threadpool
    return await anyio.to_thread.run_sync(func)
           ^^^^^^^^^^^^^^^^^^^^^^^^^^^^^^^^^^^^
  File "/Users/abdulrahman/Documents/GitHub/shoobydo/apps/backend/.venv/lib/python3.13/site-packages/anyio/to_thread.py", line 56, in run_sync
    return await get_async_backend().run_sync_in_worker_thread(
           ^^^^^^^^^^^^^^^^^^^^^^^^^^^^^^^^^^^^^^^^^^^^^^^^^^^^
        func, args, abandon_on_cancel=abandon_on_cancel, limiter=limiter
        ^^^^^^^^^^^^^^^^^^^^^^^^^^^^^^^^^^^^^^^^^^^^^^^^^^^^^^^^^^^^^^^^
    )
    ^
  File "/Users/abdulrahman/Documents/GitHub/shoobydo/apps/backend/.venv/lib/python3.13/site-packages/anyio/_backends/_asyncio.py", line 2476, in run_sync_in_worker_thread
    return await future
           ^^^^^^^^^^^^
  File "/Users/abdulrahman/Documents/GitHub/shoobydo/apps/backend/.venv/lib/python3.13/site-packages/anyio/_backends/_asyncio.py", line 967, in run
    result = context.run(func, *args)
  File "/Users/abdulrahman/Documents/GitHub/shoobydo/apps/backend/app/routers/auth.py", line 36, in login
    user = db.query(User).filter(User.email == payload.email).one_or_none()
  File "/Users/abdulrahman/Documents/GitHub/shoobydo/apps/backend/.venv/lib/python3.13/site-packages/sqlalchemy/orm/query.py", line 2785, in one_or_none
    return self._iter().one_or_none()  # type: ignore
           ~~~~~~~~~~^^
  File "/Users/abdulrahman/Documents/GitHub/shoobydo/apps/backend/.venv/lib/python3.13/site-packages/sqlalchemy/orm/query.py", line 2857, in _iter
    result: Union[ScalarResult[_T], Result[_T]] = self.session.execute(
                                                  ~~~~~~~~~~~~~~~~~~~~^
        statement,
        ^^^^^^^^^^
        params,
        ^^^^^^^
        execution_options={"_sa_orm_load_options": self.load_options},
        ^^^^^^^^^^^^^^^^^^^^^^^^^^^^^^^^^^^^^^^^^^^^^^^^^^^^^^^^^^^^^^
    )
    ^
  File "/Users/abdulrahman/Documents/GitHub/shoobydo/apps/backend/.venv/lib/python3.13/site-packages/sqlalchemy/orm/session.py", line 2365, in execute
    return self._execute_internal(
           ~~~~~~~~~~~~~~~~~~~~~~^
        statement,
        ^^^^^^^^^^
    ...<4 lines>...
        _add_event=_add_event,
        ^^^^^^^^^^^^^^^^^^^^^^
    )
    ^
  File "/Users/abdulrahman/Documents/GitHub/shoobydo/apps/backend/.venv/lib/python3.13/site-packages/sqlalchemy/orm/session.py", line 2251, in _execute_internal
    result: Result[Any] = compile_state_cls.orm_execute_statement(
                          ~~~~~~~~~~~~~~~~~~~~~~~~~~~~~~~~~~~~~~~^
        self,
        ^^^^^
    ...<4 lines>...
        conn,
        ^^^^^
    )
    ^
  File "/Users/abdulrahman/Documents/GitHub/shoobydo/apps/backend/.venv/lib/python3.13/site-packages/sqlalchemy/orm/context.py", line 306, in orm_execute_statement
    result = conn.execute(
        statement, params or {}, execution_options=execution_options
    )
  File "/Users/abdulrahman/Documents/GitHub/shoobydo/apps/backend/.venv/lib/python3.13/site-packages/sqlalchemy/engine/base.py", line 1419, in execute
    return meth(
        self,
        distilled_parameters,
        execution_options or NO_OPTIONS,
    )
  File "/Users/abdulrahman/Documents/GitHub/shoobydo/apps/backend/.venv/lib/python3.13/site-packages/sqlalchemy/sql/elements.py", line 526, in _execute_on_connection
    return connection._execute_clauseelement(
           ~~~~~~~~~~~~~~~~~~~~~~~~~~~~~~~~~^
        self, distilled_params, execution_options
        ^^^^^^^^^^^^^^^^^^^^^^^^^^^^^^^^^^^^^^^^^
    )
    ^
  File "/Users/abdulrahman/Documents/GitHub/shoobydo/apps/backend/.venv/lib/python3.13/site-packages/sqlalchemy/engine/base.py", line 1641, in _execute_clauseelement
    ret = self._execute_context(
        dialect,
    ...<8 lines>...
        cache_hit=cache_hit,
    )
  File "/Users/abdulrahman/Documents/GitHub/shoobydo/apps/backend/.venv/lib/python3.13/site-packages/sqlalchemy/engine/base.py", line 1846, in _execute_context
    return self._exec_single_context(
           ~~~~~~~~~~~~~~~~~~~~~~~~~^
        dialect, context, statement, parameters
        ^^^^^^^^^^^^^^^^^^^^^^^^^^^^^^^^^^^^^^^
    )
    ^
  File "/Users/abdulrahman/Documents/GitHub/shoobydo/apps/backend/.venv/lib/python3.13/site-packages/sqlalchemy/engine/base.py", line 1986, in _exec_single_context
    self._handle_dbapi_exception(
    ~~~~~~~~~~~~~~~~~~~~~~~~~~~~^
        e, str_statement, effective_parameters, cursor, context
        ^^^^^^^^^^^^^^^^^^^^^^^^^^^^^^^^^^^^^^^^^^^^^^^^^^^^^^^
    )
    ^
  File "/Users/abdulrahman/Documents/GitHub/shoobydo/apps/backend/.venv/lib/python3.13/site-packages/sqlalchemy/engine/base.py", line 2355, in _handle_dbapi_exception
    raise sqlalchemy_exception.with_traceback(exc_info[2]) from e
  File "/Users/abdulrahman/Documents/GitHub/shoobydo/apps/backend/.venv/lib/python3.13/site-packages/sqlalchemy/engine/base.py", line 1967, in _exec_single_context
    self.dialect.do_execute(
    ~~~~~~~~~~~~~~~~~~~~~~~^
        cursor, str_statement, effective_parameters, context
        ^^^^^^^^^^^^^^^^^^^^^^^^^^^^^^^^^^^^^^^^^^^^^^^^^^^^
    )
    ^
  File "/Users/abdulrahman/Documents/GitHub/shoobydo/apps/backend/.venv/lib/python3.13/site-packages/sqlalchemy/engine/default.py", line 951, in do_execute
    cursor.execute(statement, parameters)
    ~~~~~~~~~~~~~~^^^^^^^^^^^^^^^^^^^^^^^
sqlalchemy.exc.ProgrammingError: (psycopg2.errors.UndefinedTable) relation "users" does not exist
LINE 2: FROM users 
             ^

[SQL: SELECT users.id AS users_id, users.email AS users_email, users.hashed_password AS users_hashed_password, users.role AS users_role, users.is_active AS users_is_active, users.created_at AS users_created_at, users.updated_at AS users_updated_at 
FROM users 
WHERE users.email = %(email_1)s]
[parameters: {'email_1': 'admin@example.com'}]
(Background on this error at: https://sqlalche.me/e/20/f405)
INFO:     Shutting down
INFO:     Waiting for application shutdown.
INFO:     Application shutdown complete.
INFO:     Finished server process [17725]
